Workbook

Sheet Summary
A1: AF onboarding and framework backlog: estimate summary
A2: All figures are formulas over the Backlog sheet. Change Size, Priority or Status there and this sheet updates.
A4: Team velocity (points per sprint) | B4: 30 | C4: Assumption: example velocity, replace with your team's actual figure.
A6: By phase | B6: Stories | C6: Points | D6: Points done | E6: Sprints (at velocity)
A7: 0 - Framework refactor (CS) | B7: =COUNTIF(Backlog!$B$2:$B$84,A7) -> 26 | C7: =SUMIFS(Backlog!$J$2:$J$84,Backlog!$B$2:$B$84,A7) -> 98 | D7: =SUMIFS(Backlog!$J$2:$J$84,Backlog!$B$2:$B$84,A7,Backlog!$N$2:$N$84,"Done") -> 0 | E7: =IF($B$4>0,C7/$B$4,0) -> 3.2666667
A8: 1 - AF foundation (CSAF) | B8: =COUNTIF(Backlog!$B$2:$B$84,A8) -> 13 | C8: =SUMIFS(Backlog!$J$2:$J$84,Backlog!$B$2:$B$84,A8) -> 34 | D8: =SUMIFS(Backlog!$J$2:$J$84,Backlog!$B$2:$B$84,A8,Backlog!$N$2:$N$84,"Done") -> 0 | E8: =IF($B$4>0,C8/$B$4,0) -> 1.1333333
A9: 2 - AF web form | B9: =COUNTIF(Backlog!$B$2:$B$84,A9) -> 10 | C9: =SUMIFS(Backlog!$J$2:$J$84,Backlog!$B$2:$B$84,A9) -> 30 | D9: =SUMIFS(Backlog!$J$2:$J$84,Backlog!$B$2:$B$84,A9,Backlog!$N$2:$N$84,"Done") -> 0 | E9: =IF($B$4>0,C9/$B$4,0) -> 1
A10: 3 - AF specializations | B10: =COUNTIF(Backlog!$B$2:$B$84,A10) -> 15 | C10: =SUMIFS(Backlog!$J$2:$J$84,Backlog!$B$2:$B$84,A10) -> 50 | D10: =SUMIFS(Backlog!$J$2:$J$84,Backlog!$B$2:$B$84,A10,Backlog!$N$2:$N$84,"Done") -> 0 | E10: =IF($B$4>0,C10/$B$4,0) -> 1.6666667
A11: 4 - Test and go-live | B11: =COUNTIF(Backlog!$B$2:$B$84,A11) -> 8 | C11: =SUMIFS(Backlog!$J$2:$J$84,Backlog!$B$2:$B$84,A11) -> 29 | D11: =SUMIFS(Backlog!$J$2:$J$84,Backlog!$B$2:$B$84,A11,Backlog!$N$2:$N$84,"Done") -> 0 | E11: =IF($B$4>0,C11/$B$4,0) -> 0.96666667
A12: 5 - Future: CSTR | B12: =COUNTIF(Backlog!$B$2:$B$84,A12) -> 11 | C12: =SUMIFS(Backlog!$J$2:$J$84,Backlog!$B$2:$B$84,A12) -> 51 | D12: =SUMIFS(Backlog!$J$2:$J$84,Backlog!$B$2:$B$84,A12,Backlog!$N$2:$N$84,"Done") -> 0 | E12: =IF($B$4>0,C12/$B$4,0) -> 1.7
A13: Total | B13: =SUM(B7:B12) -> 83 | C13: =SUM(C7:C12) -> 292 | D13: =SUM(D7:D12) -> 0 | E13: =SUM(E7:E12) -> 9.7333333
A15: By priority | B15: Stories | C15: Points | D15: Points done | E15: Sprints (at velocity)
A16: P1 - Must | B16: =COUNTIF(Backlog!$L$2:$L$84,A16) -> 59 | C16: =SUMIFS(Backlog!$J$2:$J$84,Backlog!$L$2:$L$84,A16) -> 205 | D16: =SUMIFS(Backlog!$J$2:$J$84,Backlog!$L$2:$L$84,A16,Backlog!$N$2:$N$84,"Done") -> 0 | E16: =IF($B$4>0,C16/$B$4,0) -> 6.8333333
A17: P2 - Should | B17: =COUNTIF(Backlog!$L$2:$L$84,A17) -> 14 | C17: =SUMIFS(Backlog!$J$2:$J$84,Backlog!$L$2:$L$84,A17) -> 39 | D17: =SUMIFS(Backlog!$J$2:$J$84,Backlog!$L$2:$L$84,A17,Backlog!$N$2:$N$84,"Done") -> 0 | E17: =IF($B$4>0,C17/$B$4,0) -> 1.3
A18: P3 - Could / Future | B18: =COUNTIF(Backlog!$L$2:$L$84,A18) -> 10 | C18: =SUMIFS(Backlog!$J$2:$J$84,Backlog!$L$2:$L$84,A18) -> 48 | D18: =SUMIFS(Backlog!$J$2:$J$84,Backlog!$L$2:$L$84,A18,Backlog!$N$2:$N$84,"Done") -> 0 | E18: =IF($B$4>0,C18/$B$4,0) -> 1.6
A19: Total | B19: =SUM(B16:B18) -> 83 | C19: =SUM(C16:C18) -> 292 | D19: =SUM(D16:D18) -> 0 | E19: =SUM(E16:E18) -> 9.7333333
A21: By intensity | B21: Stories | C21: Points | D21: Points done | E21: Sprints (at velocity)
A22: High | B22: =COUNTIF(Backlog!$K$2:$K$84,A22) -> 23 | C22: =SUMIFS(Backlog!$J$2:$J$84,Backlog!$K$2:$K$84,A22) -> 129 | D22: =SUMIFS(Backlog!$J$2:$J$84,Backlog!$K$2:$K$84,A22,Backlog!$N$2:$N$84,"Done") -> 0 | E22: =IF($B$4>0,C22/$B$4,0) -> 4.3
A23: Medium | B23: =COUNTIF(Backlog!$K$2:$K$84,A23) -> 36 | C23: =SUMIFS(Backlog!$J$2:$J$84,Backlog!$K$2:$K$84,A23) -> 111 | D23: =SUMIFS(Backlog!$J$2:$J$84,Backlog!$K$2:$K$84,A23,Backlog!$N$2:$N$84,"Done") -> 0 | E23: =IF($B$4>0,C23/$B$4,0) -> 3.7
A24: Low | B24: =COUNTIF(Backlog!$K$2:$K$84,A24) -> 24 | C24: =SUMIFS(Backlog!$J$2:$J$84,Backlog!$K$2:$K$84,A24) -> 52 | D24: =SUMIFS(Backlog!$J$2:$J$84,Backlog!$K$2:$K$84,A24,Backlog!$N$2:$N$84,"Done") -> 0 | E24: =IF($B$4>0,C24/$B$4,0) -> 1.7333333
A25: Total | B25: =SUM(B22:B24) -> 83 | C25: =SUM(C22:C24) -> 292 | D25: =SUM(D22:D24) -> 0 | E25: =SUM(E22:E24) -> 9.7333333
A27: By size | B27: Stories | C27: Points | D27: Points done | E27: Sprints (at velocity)
A28: S | B28: =COUNTIF(Backlog!$I$2:$I$84,A28) -> 27 | C28: =SUMIFS(Backlog!$J$2:$J$84,Backlog!$I$2:$I$84,A28) -> 54 | D28: =SUMIFS(Backlog!$J$2:$J$84,Backlog!$I$2:$I$84,A28,Backlog!$N$2:$N$84,"Done") -> 0 | E28: =IF($B$4>0,C28/$B$4,0) -> 1.8
A29: M | B29: =COUNTIF(Backlog!$I$2:$I$84,A29) -> 42 | C29: =SUMIFS(Backlog!$J$2:$J$84,Backlog!$I$2:$I$84,A29) -> 126 | D29: =SUMIFS(Backlog!$J$2:$J$84,Backlog!$I$2:$I$84,A29,Backlog!$N$2:$N$84,"Done") -> 0 | E29: =IF($B$4>0,C29/$B$4,0) -> 4.2
A30: L | B30: =COUNTIF(Backlog!$I$2:$I$84,A30) -> 14 | C30: =SUMIFS(Backlog!$J$2:$J$84,Backlog!$I$2:$I$84,A30) -> 112 | D30: =SUMIFS(Backlog!$J$2:$J$84,Backlog!$I$2:$I$84,A30,Backlog!$N$2:$N$84,"Done") -> 0 | E30: =IF($B$4>0,C30/$B$4,0) -> 3.7333333
A31: Total | B31: =SUM(B28:B30) -> 83 | C31: =SUM(C28:C30) -> 292 | D31: =SUM(D28:D30) -> 0 | E31: =SUM(E28:E30) -> 9.7333333
A33: By category | B33: Stories | C33: Points | D33: Points done | E33: Sprints (at velocity)
A34: AI | B34: =COUNTIF(Backlog!$C$2:$C$84,A34) -> 3 | C34: =SUMIFS(Backlog!$J$2:$J$84,Backlog!$C$2:$C$84,A34) -> 13 | D34: =SUMIFS(Backlog!$J$2:$J$84,Backlog!$C$2:$C$84,A34,Backlog!$N$2:$N$84,"Done") -> 0 | E34: =IF($B$4>0,C34/$B$4,0) -> 0.43333333
A35: AI / business rules | B35: =COUNTIF(Backlog!$C$2:$C$84,A35) -> 2 | C35: =SUMIFS(Backlog!$J$2:$J$84,Backlog!$C$2:$C$84,A35) -> 16 | D35: =SUMIFS(Backlog!$J$2:$J$84,Backlog!$C$2:$C$84,A35,Backlog!$N$2:$N$84,"Done") -> 0 | E35: =IF($B$4>0,C35/$B$4,0) -> 0.53333333
A36: AI / email | B36: =COUNTIF(Backlog!$C$2:$C$84,A36) -> 1 | C36: =SUMIFS(Backlog!$J$2:$J$84,Backlog!$C$2:$C$84,A36) -> 3 | D36: =SUMIFS(Backlog!$J$2:$J$84,Backlog!$C$2:$C$84,A36,Backlog!$N$2:$N$84,"Done") -> 0 | E36: =IF($B$4>0,C36/$B$4,0) -> 0.1
A37: Analysis | B37: =COUNTIF(Backlog!$C$2:$C$84,A37) -> 1 | C37: =SUMIFS(Backlog!$J$2:$J$84,Backlog!$C$2:$C$84,A37) -> 3 | D37: =SUMIFS(Backlog!$J$2:$J$84,Backlog!$C$2:$C$84,A37,Backlog!$N$2:$N$84,"Done") -> 0 | E37: =IF($B$4>0,C37/$B$4,0) -> 0.1
A38: Architecture | B38: =COUNTIF(Backlog!$C$2:$C$84,A38) -> 5 | C38: =SUMIFS(Backlog!$J$2:$J$84,Backlog!$C$2:$C$84,A38) -> 13 | D38: =SUMIFS(Backlog!$J$2:$J$84,Backlog!$C$2:$C$84,A38,Backlog!$N$2:$N$84,"Done") -> 0 | E38: =IF($B$4>0,C38/$B$4,0) -> 0.43333333
A39: Background processing | B39: =COUNTIF(Backlog!$C$2:$C$84,A39) -> 2 | C39: =SUMIFS(Backlog!$J$2:$J$84,Backlog!$C$2:$C$84,A39) -> 6 | D39: =SUMIFS(Backlog!$J$2:$J$84,Backlog!$C$2:$C$84,A39,Backlog!$N$2:$N$84,"Done") -> 0 | E39: =IF($B$4>0,C39/$B$4,0) -> 0.2
A40: Case processing | B40: =COUNTIF(Backlog!$C$2:$C$84,A40) -> 6 | C40: =SUMIFS(Backlog!$J$2:$J$84,Backlog!$C$2:$C$84,A40) -> 21 | D40: =SUMIFS(Backlog!$J$2:$J$84,Backlog!$C$2:$C$84,A40,Backlog!$N$2:$N$84,"Done") -> 0 | E40: =IF($B$4>0,C40/$B$4,0) -> 0.7
A41: Configuration | B41: =COUNTIF(Backlog!$C$2:$C$84,A41) -> 4 | C41: =SUMIFS(Backlog!$J$2:$J$84,Backlog!$C$2:$C$84,A41) -> 9 | D41: =SUMIFS(Backlog!$J$2:$J$84,Backlog!$C$2:$C$84,A41,Backlog!$N$2:$N$84,"Done") -> 0 | E41: =IF($B$4>0,C41/$B$4,0) -> 0.3
A42: Configuration / DCR | B42: =COUNTIF(Backlog!$C$2:$C$84,A42) -> 2 | C42: =SUMIFS(Backlog!$J$2:$J$84,Backlog!$C$2:$C$84,A42) -> 5 | D42: =SUMIFS(Backlog!$J$2:$J$84,Backlog!$C$2:$C$84,A42,Backlog!$N$2:$N$84,"Done") -> 0 | E42: =IF($B$4>0,C42/$B$4,0) -> 0.16666667
A43: Correspondence | B43: =COUNTIF(Backlog!$C$2:$C$84,A43) -> 2 | C43: =SUMIFS(Backlog!$J$2:$J$84,Backlog!$C$2:$C$84,A43) -> 6 | D43: =SUMIFS(Backlog!$J$2:$J$84,Backlog!$C$2:$C$84,A43,Backlog!$N$2:$N$84,"Done") -> 0 | E43: =IF($B$4>0,C43/$B$4,0) -> 0.2
A44: Data governance | B44: =COUNTIF(Backlog!$C$2:$C$84,A44) -> 1 | C44: =SUMIFS(Backlog!$J$2:$J$84,Backlog!$C$2:$C$84,A44) -> 3 | D44: =SUMIFS(Backlog!$J$2:$J$84,Backlog!$C$2:$C$84,A44,Backlog!$N$2:$N$84,"Done") -> 0 | E44: =IF($B$4>0,C44/$B$4,0) -> 0.1
A45: Data migration | B45: =COUNTIF(Backlog!$C$2:$C$84,A45) -> 1 | C45: =SUMIFS(Backlog!$J$2:$J$84,Backlog!$C$2:$C$84,A45) -> 3 | D45: =SUMIFS(Backlog!$J$2:$J$84,Backlog!$C$2:$C$84,A45,Backlog!$N$2:$N$84,"Done") -> 0 | E45: =IF($B$4>0,C45/$B$4,0) -> 0.1
... A63: Validation | B63: =COUNTIF(Backlog!$C$2:$C$84,A63) -> 1 | C63: =SUMIFS(Backlog!$J$2:$J$84,Backlog!$C$2:$C$84,A63) -> 3 | D63: =SUMIFS(Backlog!$J$2:$J$84,Backlog!$C$2:$C$84,A63,Backlog!$N$2:$N$84,"Done") -> 0 | E63: =IF($B$4>0,C63/$B$4,0) -> 0.1
...

Sheet Legend
A1: Legend and how to use this workbook
A2: Edit only the blue cells and the backlog columns Size, Intensity, Priority, Status, Owner. Story points and the Summary sheet recalculate from them.
A4: T-shirt size | B4: Story points | C4: Meaning
A5: S | B5: 2 | C5: Small, well understood change in one layer; little regression impact | D5: Points per size as given by you (S=2, M=3, L=8); change the blue cells to re-weight.
A6: M | B6: 3 | C6: Moderate change, a few rules or instances; some design or testing effort
A7: L | B7: 8 | C7: Large or cross-cutting change; refactoring, several layers, or heavy regression
A9: Intensity | C9: Meaning (technical risk and regression impact)
A10: High | C10: Touches framework or security/isolation; failure affects Trinity or data separation
A11: Medium | C11: Some design choices or cross-layer effects; contained regression
A12: Low | C12: Configuration or AF-only change with local impact
A14: Priority | C14: Meaning
A15: P1 - Must | C15: Needed for Adrian Flux go-live
A16: P2 - Should | C16: Important; can follow shortly after go-live or ship if capacity allows
A17: P3 - Could / Future | C17: Future state (CSTR framework separation) or only if AF needs it
A19: Status | C19: Meaning
A20: Not started
A21: In progress
A22: Blocked
A23: Done
A25: Story IDs: F = Phase 0 framework refactor (CS), A = Phase 1 AF foundation (CSAF), W = Phase 2 AF web form (CSAFWebExt), S = Phase 3 AF specializations, T = Phase 4 test and go-live, R = Phase 5 future CSTR. Section numbers refer to the framework document.

Sheet Backlog
A1: ID | B1: Phase | C1: Category | D1: Story title | E1: Description / scope | F1: Acceptance criteria | G1: Layer / app | H1: Doc section | I1: Size | J1: Story points | K1: Intensity | L1: Priority | M1: Depends on | N1: Status | O1: Owner / notes
A2: F-01 | B2: 0 - Framework refactor (CS) | C2: Analysis | D2: Capability inventory and rule tagging | E2: List every Trinity capability and its rules; tag each Framework / Extend / Specialize. | F2: Inventory signed off; every rule in the FNOL flow tagged; extension point list agreed. | G2: CS | H2: 2, 13 | I2: M | J2: =IFERROR(INDEX(Legend!$B$5:$B$7,MATCH(I2,Legend!$A$5:$A$7,0)),0) -> 3 | K2: Medium | L2: P1 - Must | N2: Not started
A3: F-02 | B3: 0 - Framework refactor (CS) | C3: Refactoring | D3: Scan CS rulesets for coverholder literals | E3: Search CS and CSWebExt for 'Trinity', TRI-, mailbox domains, class names, case type IDs, logos. | F3: Report of all hits with owning rule; each hit mapped to a refactoring story. | G3: CS | H3: 2, 16 | I3: S | J3: =IFERROR(INDEX(Legend!$B$5:$B$7,MATCH(I3,Legend!$A$5:$A$7,0)),0) -> 2 | K3: Low | L3: P1 - Must | M3: F-01 | N3: Not started
A4: F-03 | B4: 0 - Framework refactor (CS) | C4: Configuration | D4: Coverholder configuration data type | E4: Create HCC-CS-Data-CoverholderConfig, table and D_CoverholderConfig (node, keyed by CoverholderCode); add TRI row. | F4: Data page returns TRI row; refresh on table change; PegaUnit on lookup. | G4: CS | H4: 6 | I4: M | J4: =IFERROR(INDEX(Legend!$B$5:$B$7,MATCH(I4,Legend!$A$5:$A$7,0)),0) -> 3 | K4: Medium | L4: P1 - Must | M4: F-01 | N4: Not started
A5: F-04 | B5: 0 - Framework refactor (CS) | C5: Configuration / DCR | D5: Application context data page | E5: Create HCC-CS-Data-AppContext, D_CSAppContext (requestor) and LoadAppContext with Trinity values. | F5: D_CSAppContext returns TRI and class names in CS context; documented as overridable per ruleset. | G5: CS | H5: 6 | I5: M | J5: =IFERROR(INDEX(Legend!$B$5:$B$7,MATCH(I5,Legend!$A$5:$A$7,0)),0) -> 3 | K5: Medium | L5: P1 - Must | M5: F-03 | N5: Not started
A6: F-05 | B6: 0 - Framework refactor (CS) | C6: Data model | D6: CoverholderCode on cases | E6: Add .CoverholderCode to HCC-CS-Work; set in pyDefault of HCC-CS-Work-FNOL; expose as column. | F6: New Trinity cases carry TRI; column populated and indexed. | G6: CS | H6: 6 | I6: S | J6: =IFERROR(INDEX(Legend!$B$5:$B$7,MATCH(I6,Legend!$A$5:$A$7,0)),0) -> 2 | K6: Low | L6: P1 - Must | M6: F-03 | N6: Not started
A7: F-06 | B7: 0 - Framework refactor (CS) | C7: Data migration | D7: Backfill CoverholderCode on existing cases | E7: Backfill TRI on open and closed Trinity FNOL and triage cases. | F7: All existing cases have TRI; reconciliation count matches; run log kept. | G7: CS | H7: 6, 16 | I7: M | J7: =IFERROR(INDEX(Legend!$B$5:$B$7,MATCH(I7,Legend!$A$5:$A$7,0)),0) -> 3 | K7: Medium | L7: P1 - Must | M7: F-05 | N7: Not started
A8: F-07 | B8: 0 - Framework refactor (CS) | C8: Configuration / DCR | D8: GetCoverholderCode resolver | E8: Shared rule: case .CoverholderCode first, else D_CSAppContext. | F8: Unit tests for case, case-less and background contexts. | G8: CS | H8: 6 | I8: S | J8: =IFERROR(INDEX(Legend!$B$5:$B$7,MATCH(I8,Legend!$A$5:$A$7,0)),0) -> 2 | K8: Low | L8: P1 - Must | M8: F-04, F-05 | N8: Not started
A9: F-08 | B9: 0 - Framework refactor (CS) | C9: Refactoring | D9: Replace hard-coded values with config lookups | E9: Replace literal class names, email accounts, prefixes, patterns, mailboxes found in F-02. | F9: Zero literal hits in re-scan (except Trinity _Ext defaults); Trinity regression green. | G9: CS | H9: 3, 6 | I9: L | J9: =IFERROR(INDEX(Legend!$B$5:$B$7,MATCH(I9,Legend!$A$5:$A$7,0)),0) -> 8 | K9: High | L9: P1 - Must | M9: F-02, F-07 | N9: Not started
A10: F-09 | B10: 0 - Framework refactor (CS) | C10: Case processing | D10: Refactor NewDefaults into template + extensions | E10: Split NewDefaults; create DuplicateCheckCriteria_Ext, IsDuplicate_Ext, OnDuplicateFound_Ext, NewDefaults_Ext with Trinity defaults. | F10: Trinity duplicate outcomes identical on regression set; PegaUnit per _Ext. | G10: CS | H10: 10 | I10: L | J10: =IFERROR(INDEX(Legend!$B$5:$B$7,MATCH(I10,Legend!$A$5:$A$7,0)),0) -> 8 | K10: High | L10: P1 - Must | M10: F-01 | N10: Not started
A11: F-10 | B11: 0 - Framework refactor (CS) | C11: Case processing | D11: Class-aware duplicate candidate data page | E11: D_DuplicateCandidates runs the duplicate report in the case's own class. | F11: Query hits only the case's table; response time within agreed limit. | G11: CS | H11: 10 | I11: M | J11: =IFERROR(INDEX(Legend!$B$5:$B$7,MATCH(I11,Legend!$A$5:$A$7,0)),0) -> 3 | K11: Medium | L11: P1 - Must | M11: F-09 | N11: Not started
A12: F-11 | B12: 0 - Framework refactor (CS) | C12: Correspondence | D12: Refactor confirmation correspondence | E12: Split shared and coverholder paragraphs; sender account from config; ConfirmationRecipients_Ext. | F12: Trinity emails unchanged; account name not hard-coded. | G12: CS | H12: 11 | I12: M | J12: =IFERROR(INDEX(Legend!$B$5:$B$7,MATCH(I12,Legend!$A$5:$A$7,0)),0) -> 3 | K12: Medium | L12: P1 - Must | M12: F-03 | N12: Not started
A13: F-12 | B13: 0 - Framework refactor (CS) | C13: Document generation | D13: Refactor claim summary PDF | E13: Shared claim-details section; ClaimSummaryPDF override point; file name prefix and category from config. | F13: Trinity PDF identical; file name built from config. | G13: CS | H13: 11 | I13: M | J13: =IFERROR(INDEX(Legend!$B$5:$B$7,MATCH(I13,Legend!$A$5:$A$7,0)),0) -> 3 | K13: Medium | L13: P1 - Must | M13: F-03 | N13: Not started
A14: F-13 | B14: 0 - Framework refactor (CS) | C14: AI | D14: Refactor AI image analysis configuration | E14: Move prompt and thresholds to config or ImageAnalysisPrompt_Ext; confirm QP context handling. | F14: Trinity analysis results unchanged; no literal prompt in framework activity. | G14: CS | H14: 11, 14 | I14: M | J14: =IFERROR(INDEX(Legend!$B$5:$B$7,MATCH(I14,Legend!$A$5:$A$7,0)),0) -> 3 | K14: Medium | L14: P1 - Must | M14: F-03, F-26 | N14: Not started
... A23: F-22 | B23: 0 - Framework refactor (CS) | C23: UI / DX component | D23: Move component to shared component ruleset | E23: Publish the custom component into a shared CS component ruleset. | F23: Single component version used by CSWebExt; old copy withdrawn. | G23: CS | H23: 4, 8 | I23: S | J23: =IFERROR(INDEX(Legend!$B$5:$B$7,MATCH(I23,Legend!$A$5:$A$7,0)),0) -> 2 | K23: Medium | L23: P1 - Must | M23: F-21 | N23: Not started
A24: F-23 | B24: 0 - Framework refactor (CS) | C24: DevOps | D24: Bundle key-parity check | E24: Pipeline script comparing keys across web app bundles. | F24: Pipeline fails on missing keys. | G24: DevOps | H24: 8 | I24: S | J24: =IFERROR(INDEX(Legend!$B$5:$B$7,MATCH(I24,Legend!$A$5:$A$7,0)),0) -> 2 | K24: Low | L24: P2 - Should | N24: Not started
A25: F-24 | B25: 0 - Framework refactor (CS) | C25: Governance | D25: Extension point catalogue | E25: Document each _Ext rule: purpose, inputs, outputs, default. | F25: Catalogue published and linked from rule descriptions. | G25: CS | H25: 13 | I25: S | J25: =IFERROR(INDEX(Legend!$B$5:$B$7,MATCH(I25,Legend!$A$5:$A$7,0)),0) -> 2 | K25: Low | L25: P2 - Should | M25: F-09, F-15 | N25: Not started
A26: F-25 | B26: 0 - Framework refactor (CS) | C26: Testing | D26: Trinity regression and CS framework release | E26: Full Trinity regression after Phase 0; release CS version. | F26: Regression results identical to baseline; CS version locked. | G26: CS | H26: 15, 16 | I26: L | J26: =IFERROR(INDEX(Legend!$B$5:$B$7,MATCH(I26,Legend!$A$5:$A$7,0)),0) -> 8 | K26: High | L26: P1 - Must | M26: F-08 to F-22 | N26: Not started
A27: F-26 | B27: 0 - Framework refactor (CS) | C27: Architecture | D27: Background processing inventory | E27: List QPs, job schedulers, agents, SLAs in FNOL flow and their access-group context. | F27: Inventory with decision per item: separate AF instance or case-resolved. | G27: CS | H27: 14 | I27: M | J27: =IFERROR(INDEX(Legend!$B$5:$B$7,MATCH(I27,Legend!$A$5:$A$7,0)),0) -> 3 | K27: Medium | L27: P1 - Must | M27: F-01 | N27: Not started
A28: A-01 | B28: 1 - AF foundation (CSAF) | C28: Architecture | D28: Create CSAF application | E28: CSAF built on CS; rulesets CSAF, CSAFInt, CSAFData; case types list. | F28: Application opens; only AF case types shown. | G28: CSAF | H28: 4 | I28: S | J28: =IFERROR(INDEX(Legend!$B$5:$B$7,MATCH(I28,Legend!$A$5:$A$7,0)),0) -> 2 | K28: Low | L28: P1 - Must | M28: F-25 | N28: Not started
A29: A-02 | B29: 1 - AF foundation (CSAF) | C29: Data model | D29: AF class group and classes | E29: HCC-CSAF-Work class group, HCC-CSAF-Work-FNOL with directed parent HCC-CS-Work-FNOL; table mappings. | F29: Classes created; rule resolution shows CS rules inherited. | G29: CSAF | H29: 5 | I29: M | J29: =IFERROR(INDEX(Legend!$B$5:$B$7,MATCH(I29,Legend!$A$5:$A$7,0)),0) -> 3 | K29: Medium | L29: P1 - Must | M29: A-01 | N29: Not started
A30: A-03 | B30: 1 - AF foundation (CSAF) | C30: Database | D30: AF database tables (DDL) | E30: Case, history and index tables with columns matching CS exposed columns plus duplicate-check indexes. | F30: DDL executed in all environments; column parity verified. | G30: DBA | H30: 5 | I30: M | J30: =IFERROR(INDEX(Legend!$B$5:$B$7,MATCH(I30,Legend!$A$5:$A$7,0)),0) -> 3 | K30: Medium | L30: P1 - Must | M30: A-02 | N30: Not started
A31: A-04 | B31: 1 - AF foundation (CSAF) | C31: Case processing | D31: AF case type | E31: Thin case type rule calling CS processes; work ID prefix; pyDefault sets AF. | F31: AF case created with correct prefix and CoverholderCode AF. | G31: CSAF | H31: 10 | I31: M | J31: =IFERROR(INDEX(Legend!$B$5:$B$7,MATCH(I31,Legend!$A$5:$A$7,0)),0) -> 3 | K31: Medium | L31: P1 - Must | M31: A-02, A-03 | N31: Not started
A32: A-05 | B32: 1 - AF foundation (CSAF) | C32: Testing | D32: Stage-list comparison test | E32: Unit test comparing CS and AF case type stages. | F32: Test fails when stages diverge unexpectedly. | G32: CSAF | H32: 10 | I32: S | J32: =IFERROR(INDEX(Legend!$B$5:$B$7,MATCH(I32,Legend!$A$5:$A$7,0)),0) -> 2 | K32: Low | L32: P2 - Should | M32: A-04 | N32: Not started
A33: A-06 | B33: 1 - AF foundation (CSAF) | C33: Configuration | D33: AF config row and context override | E33: AF row in config table; LoadAppContext override in CSAF ruleset. | F33: D_CSAppContext returns AF in CSAF context. | G33: CSAF | H33: 6 | I33: S | J33: =IFERROR(INDEX(Legend!$B$5:$B$7,MATCH(I33,Legend!$A$5:$A$7,0)),0) -> 2 | K33: Low | L33: P1 - Must | M33: A-01, F-04 | N33: Not started
A34: A-07 | B34: 1 - AF foundation (CSAF) | C34: Data model | D34: AF LOV data type | E34: HCC-CSAF-Data-LOV, own table, AF-only properties, data load, added to app data types. | F34: AF dropdowns load AF values via shared data pages. | G34: CSAF | H34: 9 | I34: M | J34: =IFERROR(INDEX(Legend!$B$5:$B$7,MATCH(I34,Legend!$A$5:$A$7,0)),0) -> 3 | K34: Medium | L34: P1 - Must | M34: A-02, F-20 | N34: Not started
A35: A-08 | B35: 1 - AF foundation (CSAF) | C35: Data model | D35: Other AF data tables | E35: Apply LOV pattern to other web form / validation tables. | F35: Each table loads AF data through shared data pages. | G35: CSAF | H35: 9 | I35: M | J35: =IFERROR(INDEX(Legend!$B$5:$B$7,MATCH(I35,Legend!$A$5:$A$7,0)),0) -> 3 | K35: Medium | L35: P2 - Should | M35: A-07 | N35: Not started
A36: A-09 | B36: 1 - AF foundation (CSAF) | C36: Security | D36: AF roles, AROs and access groups | E36: Access roles depending on CS roles; AROs on HCC-CSAF-; access groups ClaimHandler, Supervisor, Background, Admin. | F36: AF users access only AF cases; Trinity users cannot open AF cases. | G36: CSAF | H36: 7 | I36: M | J36: =IFERROR(INDEX(Legend!$B$5:$B$7,MATCH(I36,Legend!$A$5:$A$7,0)),0) -> 3 | K36: High | L36: P1 - Must | M36: A-02 | N36: Not started
... A55: S-05 | B55: 3 - AF specializations | C55: Integration / email | D55: AF validation email | E55: AF template, recipient mailbox, subject with AF ID pattern. | F55: AF validation team receives request with parsable subject. | G55: CSAF | H55: 12 | I55: S | J55: =IFERROR(INDEX(Legend!$B$5:$B$7,MATCH(I55,Legend!$A$5:$A$7,0)),0) -> 2 | K55: Low | L55: P1 - Must | M55: F-14 | N55: Not started
A56: S-06 | B56: 3 - AF specializations | C56: Integration / email | D56: AF email accounts | E56: Inbound and outbound AF email accounts with modern auth; secrets in auth profile. | F56: Accounts connect in all environments. | G56: CSAF | H56: 12 | I56: S | J56: =IFERROR(INDEX(Legend!$B$5:$B$7,MATCH(I56,Legend!$A$5:$A$7,0)),0) -> 2 | K56: Medium | L56: P1 - Must | N56: Not started
A57: S-07 | B57: 3 - AF specializations | C57: Integration / email | D57: AF email channel and listener | E57: Email channel in CSAF; generated listener and service email; service package access group CSAF:Background. | F57: AF reply creates triage case in CSAF context with CoverholderCode AF. | G57: CSAF | H57: 12 | I57: M | J57: =IFERROR(INDEX(Legend!$B$5:$B$7,MATCH(I57,Legend!$A$5:$A$7,0)),0) -> 3 | K57: High | L57: P1 - Must | M57: S-06, A-09, F-16 | N57: Not started
A58: S-08 | B58: 3 - AF specializations | C58: AI / email | D58: AF triage extension overrides | E58: Override triage _Ext rules in CSAF ruleset only where AF replies differ. | F58: AF replies classified, linked and parsed; Trinity unaffected. | G58: CSAF | H58: 6, 12 | I58: M | J58: =IFERROR(INDEX(Legend!$B$5:$B$7,MATCH(I58,Legend!$A$5:$A$7,0)),0) -> 3 | K58: High | L58: P1 - Must | M58: F-15, S-07 | N58: Not started
A59: S-09 | B59: 3 - AF specializations | C59: AI | D59: AF NLP / text analytics model | E59: Separate AF model only if AF reply format differs materially. | F59: Model accuracy on AF sample meets agreed threshold. | G59: CSAF | H59: 12 | I59: L | J59: =IFERROR(INDEX(Legend!$B$5:$B$7,MATCH(I59,Legend!$A$5:$A$7,0)),0) -> 8 | K59: High | L59: P2 - Should | M59: S-08 | N59: Not started
A60: S-10 | B60: 3 - AF specializations | C60: AI / business rules | D60: AF parsed-data mapping and validations | E60: AF overrides of MapParsedPolicyData_Ext and ApplyPolicyValidations_Ext. | F60: AF review tabs show correct data and AF validation outcomes. | G60: CSAF | H60: 12 | I60: L | J60: =IFERROR(INDEX(Legend!$B$5:$B$7,MATCH(I60,Legend!$A$5:$A$7,0)),0) -> 8 | K60: High | L60: P1 - Must | M60: F-17, S-08 | N60: Not started
A61: S-11 | B61: 3 - AF specializations | C61: UI | D61: AF review view overrides | E61: View overrides only for AF-only fields. | F61: AF-only fields visible on review tabs. | G61: CSAF | H61: 12 | I61: S | J61: =IFERROR(INDEX(Legend!$B$5:$B$7,MATCH(I61,Legend!$A$5:$A$7,0)),0) -> 2 | K61: Low | L61: P2 - Should | M61: S-10 | N61: Not started
A62: S-12 | B62: 3 - AF specializations | C62: Background processing | D62: AF queue processors and job schedulers | E62: AF instances with CSAF:Background, or verified case-resolved, per F-26. | F62: AF background items use AF templates, accounts and rules. | G62: CSAF | H62: 14 | I62: M | J62: =IFERROR(INDEX(Legend!$B$5:$B$7,MATCH(I62,Legend!$A$5:$A$7,0)),0) -> 3 | K62: High | L62: P1 - Must | M62: F-26, A-09 | N62: Not started
A63: S-13 | B63: 3 - AF specializations | C63: Integration | D63: AF Libra entity / book code | E63: Capture and display AF entity code if Libra requires it. | F63: Libra ID and entity stored on AF case. | G63: CSAF | H63: 12 | I63: S | J63: =IFERROR(INDEX(Legend!$B$5:$B$7,MATCH(I63,Legend!$A$5:$A$7,0)),0) -> 2 | K63: Low | L63: P3 - Could / Future | M63: F-19 | N63: Not started
A64: S-14 | B64: 3 - AF specializations | C64: Reporting | D64: AF reports and extracts | E64: AF report definitions; CoverholderCode in BIX / warehouse extracts. | F64: AF MI available; extracts split by coverholder. | G64: CSAF | H64: 14 | I64: M | J64: =IFERROR(INDEX(Legend!$B$5:$B$7,MATCH(I64,Legend!$A$5:$A$7,0)),0) -> 3 | K64: Medium | L64: P2 - Should | M64: A-03 | N64: Not started
A65: S-15 | B65: 3 - AF specializations | C65: Data governance | D65: AF search, retention and archiving | E65: Search config for AF classes; archive/purge policies for AF case and triage. | F65: Policies configured and tested in non-prod. | G65: CSAF | H65: 14 | I65: M | J65: =IFERROR(INDEX(Legend!$B$5:$B$7,MATCH(I65,Legend!$A$5:$A$7,0)),0) -> 3 | K65: Medium | L65: P2 - Should | M65: A-03 | N65: Not started
A66: T-01 | B66: 4 - Test and go-live | C66: Testing | D66: AF end-to-end scenario suite | E66: Submit, duplicate, emails, AI, validation reply, triage, Libra, resolve. | F66: All AF scenarios pass in staging. | G66: DevOps | H66: 15 | I66: L | J66: =IFERROR(INDEX(Legend!$B$5:$B$7,MATCH(I66,Legend!$A$5:$A$7,0)),0) -> 8 | K66: High | L66: P1 - Must | M66: Phase 3 | N66: Not started
...
