Workbook

Sheet Summary
A1: CS framework changes and CSAF (Adrian Flux) implementation: estimate summary
A2: All figures are formulas over the Backlog sheet. Change Size, Priority or Status there and this sheet updates.
A4: Team velocity (points per sprint) | B4: 20 | C4: Assumption: example velocity, replace with your team's actual figure.
A6: By phase | B6: Stories | C6: Points | D6: Points done | E6: Sprints (at velocity)
A7: 0 - Framework refactor (CS) | B7: =COUNTIF(Backlog!$B$2:$B$75,A7) -> 27 | C7: =SUMIFS(Backlog!$J$2:$J$75,Backlog!$B$2:$B$75,A7) -> 100 | D7: =SUMIFS(Backlog!$J$2:$J$75,Backlog!$B$2:$B$75,A7,Backlog!$N$2:$N$75,"Done") -> 0 | E7: =IF($B$4>0,C7/$B$4,0) -> 5
A8: 1 - AF foundation (CSAF) | B8: =COUNTIF(Backlog!$B$2:$B$75,A8) -> 13 | C8: =SUMIFS(Backlog!$J$2:$J$75,Backlog!$B$2:$B$75,A8) -> 34 | D8: =SUMIFS(Backlog!$J$2:$J$75,Backlog!$B$2:$B$75,A8,Backlog!$N$2:$N$75,"Done") -> 0 | E8: =IF($B$4>0,C8/$B$4,0) -> 1.7
A9: 2 - AF web form | B9: =COUNTIF(Backlog!$B$2:$B$75,A9) -> 10 | C9: =SUMIFS(Backlog!$J$2:$J$75,Backlog!$B$2:$B$75,A9) -> 30 | D9: =SUMIFS(Backlog!$J$2:$J$75,Backlog!$B$2:$B$75,A9,Backlog!$N$2:$N$75,"Done") -> 0 | E9: =IF($B$4>0,C9/$B$4,0) -> 1.5
A10: 3 - AF specializations | B10: =COUNTIF(Backlog!$B$2:$B$75,A10) -> 15 | C10: =SUMIFS(Backlog!$J$2:$J$75,Backlog!$B$2:$B$75,A10) -> 50 | D10: =SUMIFS(Backlog!$J$2:$J$75,Backlog!$B$2:$B$75,A10,Backlog!$N$2:$N$75,"Done") -> 0 | E10: =IF($B$4>0,C10/$B$4,0) -> 2.5
A11: 4 - Test and go-live | B11: =COUNTIF(Backlog!$B$2:$B$75,A11) -> 9 | C11: =SUMIFS(Backlog!$J$2:$J$75,Backlog!$B$2:$B$75,A11) -> 32 | D11: =SUMIFS(Backlog!$J$2:$J$75,Backlog!$B$2:$B$75,A11,Backlog!$N$2:$N$75,"Done") -> 0 | E11: =IF($B$4>0,C11/$B$4,0) -> 1.6
A12: Total | B12: =SUM(B7:B11) -> 74 | C12: =SUM(C7:C11) -> 246 | D12: =SUM(D7:D11) -> 0 | E12: =SUM(E7:E11) -> 12.3
A14: By priority | B14: Stories | C14: Points | D14: Points done | E14: Sprints (at velocity)
A15: P1 - Must | B15: =COUNTIF(Backlog!$L$2:$L$75,A15) -> 59 | C15: =SUMIFS(Backlog!$J$2:$J$75,Backlog!$L$2:$L$75,A15) -> 205 | D15: =SUMIFS(Backlog!$J$2:$J$75,Backlog!$L$2:$L$75,A15,Backlog!$N$2:$N$75,"Done") -> 0 | E15: =IF($B$4>0,C15/$B$4,0) -> 10.25
A16: P2 - Should | B16: =COUNTIF(Backlog!$L$2:$L$75,A16) -> 14 | C16: =SUMIFS(Backlog!$J$2:$J$75,Backlog!$L$2:$L$75,A16) -> 39 | D16: =SUMIFS(Backlog!$J$2:$J$75,Backlog!$L$2:$L$75,A16,Backlog!$N$2:$N$75,"Done") -> 0 | E16: =IF($B$4>0,C16/$B$4,0) -> 1.95
A17: P3 - Could | B17: =COUNTIF(Backlog!$L$2:$L$75,A17) -> 1 | C17: =SUMIFS(Backlog!$J$2:$J$75,Backlog!$L$2:$L$75,A17) -> 2 | D17: =SUMIFS(Backlog!$J$2:$J$75,Backlog!$L$2:$L$75,A17,Backlog!$N$2:$N$75,"Done") -> 0 | E17: =IF($B$4>0,C17/$B$4,0) -> 0.1
A18: Total | B18: =SUM(B15:B17) -> 74 | C18: =SUM(C15:C17) -> 246 | D18: =SUM(D15:D17) -> 0 | E18: =SUM(E15:E17) -> 12.3
A20: By intensity | B20: Stories | C20: Points | D20: Points done | E20: Sprints (at velocity)
A21: High | B21: =COUNTIF(Backlog!$K$2:$K$75,A21) -> 19 | C21: =SUMIFS(Backlog!$J$2:$J$75,Backlog!$K$2:$K$75,A21) -> 107 | D21: =SUMIFS(Backlog!$J$2:$J$75,Backlog!$K$2:$K$75,A21,Backlog!$N$2:$N$75,"Done") -> 0 | E21: =IF($B$4>0,C21/$B$4,0) -> 5.35
A22: Medium | B22: =COUNTIF(Backlog!$K$2:$K$75,A22) -> 31 | C22: =SUMIFS(Backlog!$J$2:$J$75,Backlog!$K$2:$K$75,A22) -> 87 | D22: =SUMIFS(Backlog!$J$2:$J$75,Backlog!$K$2:$K$75,A22,Backlog!$N$2:$N$75,"Done") -> 0 | E22: =IF($B$4>0,C22/$B$4,0) -> 4.35
A23: Low | B23: =COUNTIF(Backlog!$K$2:$K$75,A23) -> 24 | C23: =SUMIFS(Backlog!$J$2:$J$75,Backlog!$K$2:$K$75,A23) -> 52 | D23: =SUMIFS(Backlog!$J$2:$J$75,Backlog!$K$2:$K$75,A23,Backlog!$N$2:$N$75,"Done") -> 0 | E23: =IF($B$4>0,C23/$B$4,0) -> 2.6
A24: Total | B24: =SUM(B21:B23) -> 74 | C24: =SUM(C21:C23) -> 246 | D24: =SUM(D21:D23) -> 0 | E24: =SUM(E21:E23) -> 12.3
A26: By size | B26: Stories | C26: Points | D26: Points done | E26: Sprints (at velocity)
A27: S | B27: =COUNTIF(Backlog!$I$2:$I$75,A27) -> 26 | C27: =SUMIFS(Backlog!$J$2:$J$75,Backlog!$I$2:$I$75,A27) -> 52 | D27: =SUMIFS(Backlog!$J$2:$J$75,Backlog!$I$2:$I$75,A27,Backlog!$N$2:$N$75,"Done") -> 0 | E27: =IF($B$4>0,C27/$B$4,0) -> 2.6
A28: M | B28: =COUNTIF(Backlog!$I$2:$I$75,A28) -> 38 | C28: =SUMIFS(Backlog!$J$2:$J$75,Backlog!$I$2:$I$75,A28) -> 114 | D28: =SUMIFS(Backlog!$J$2:$J$75,Backlog!$I$2:$I$75,A28,Backlog!$N$2:$N$75,"Done") -> 0 | E28: =IF($B$4>0,C28/$B$4,0) -> 5.7
A29: L | B29: =COUNTIF(Backlog!$I$2:$I$75,A29) -> 10 | C29: =SUMIFS(Backlog!$J$2:$J$75,Backlog!$I$2:$I$75,A29) -> 80 | D29: =SUMIFS(Backlog!$J$2:$J$75,Backlog!$I$2:$I$75,A29,Backlog!$N$2:$N$75,"Done") -> 0 | E29: =IF($B$4>0,C29/$B$4,0) -> 4
A30: Total | B30: =SUM(B27:B29) -> 74 | C30: =SUM(C27:C29) -> 246 | D30: =SUM(D27:D29) -> 0 | E30: =SUM(E27:E29) -> 12.3
A32: By category | B32: Stories | C32: Points | D32: Points done | E32: Sprints (at velocity)
A33: AI | B33: =COUNTIF(Backlog!$C$2:$C$75,A33) -> 3 | C33: =SUMIFS(Backlog!$J$2:$J$75,Backlog!$C$2:$C$75,A33) -> 13 | D33: =SUMIFS(Backlog!$J$2:$J$75,Backlog!$C$2:$C$75,A33,Backlog!$N$2:$N$75,"Done") -> 0 | E33: =IF($B$4>0,C33/$B$4,0) -> 0.65
A34: AI / business rules | B34: =COUNTIF(Backlog!$C$2:$C$75,A34) -> 2 | C34: =SUMIFS(Backlog!$J$2:$J$75,Backlog!$C$2:$C$75,A34) -> 16 | D34: =SUMIFS(Backlog!$J$2:$J$75,Backlog!$C$2:$C$75,A34,Backlog!$N$2:$N$75,"Done") -> 0 | E34: =IF($B$4>0,C34/$B$4,0) -> 0.8
A35: AI / email | B35: =COUNTIF(Backlog!$C$2:$C$75,A35) -> 1 | C35: =SUMIFS(Backlog!$J$2:$J$75,Backlog!$C$2:$C$75,A35) -> 3 | D35: =SUMIFS(Backlog!$J$2:$J$75,Backlog!$C$2:$C$75,A35,Backlog!$N$2:$N$75,"Done") -> 0 | E35: =IF($B$4>0,C35/$B$4,0) -> 0.15
A36: Analysis | B36: =COUNTIF(Backlog!$C$2:$C$75,A36) -> 1 | C36: =SUMIFS(Backlog!$J$2:$J$75,Backlog!$C$2:$C$75,A36) -> 3 | D36: =SUMIFS(Backlog!$J$2:$J$75,Backlog!$C$2:$C$75,A36,Backlog!$N$2:$N$75,"Done") -> 0 | E36: =IF($B$4>0,C36/$B$4,0) -> 0.15
A37: Architecture | B37: =COUNTIF(Backlog!$C$2:$C$75,A37) -> 3 | C37: =SUMIFS(Backlog!$J$2:$J$75,Backlog!$C$2:$C$75,A37) -> 7 | D37: =SUMIFS(Backlog!$J$2:$J$75,Backlog!$C$2:$C$75,A37,Backlog!$N$2:$N$75,"Done") -> 0 | E37: =IF($B$4>0,C37/$B$4,0) -> 0.35
A38: Background processing | B38: =COUNTIF(Backlog!$C$2:$C$75,A38) -> 1 | C38: =SUMIFS(Backlog!$J$2:$J$75,Backlog!$C$2:$C$75,A38) -> 3 | D38: =SUMIFS(Backlog!$J$2:$J$75,Backlog!$C$2:$C$75,A38,Backlog!$N$2:$N$75,"Done") -> 0 | E38: =IF($B$4>0,C38/$B$4,0) -> 0.15
A39: Case processing | B39: =COUNTIF(Backlog!$C$2:$C$75,A39) -> 6 | C39: =SUMIFS(Backlog!$J$2:$J$75,Backlog!$C$2:$C$75,A39) -> 21 | D39: =SUMIFS(Backlog!$J$2:$J$75,Backlog!$C$2:$C$75,A39,Backlog!$N$2:$N$75,"Done") -> 0 | E39: =IF($B$4>0,C39/$B$4,0) -> 1.05
A40: Configuration | B40: =COUNTIF(Backlog!$C$2:$C$75,A40) -> 3 | C40: =SUMIFS(Backlog!$J$2:$J$75,Backlog!$C$2:$C$75,A40) -> 7 | D40: =SUMIFS(Backlog!$J$2:$J$75,Backlog!$C$2:$C$75,A40,Backlog!$N$2:$N$75,"Done") -> 0 | E40: =IF($B$4>0,C40/$B$4,0) -> 0.35
A41: Configuration / DCR | B41: =COUNTIF(Backlog!$C$2:$C$75,A41) -> 2 | C41: =SUMIFS(Backlog!$J$2:$J$75,Backlog!$C$2:$C$75,A41) -> 5 | D41: =SUMIFS(Backlog!$J$2:$J$75,Backlog!$C$2:$C$75,A41,Backlog!$N$2:$N$75,"Done") -> 0 | E41: =IF($B$4>0,C41/$B$4,0) -> 0.25
A42: Correspondence | B42: =COUNTIF(Backlog!$C$2:$C$75,A42) -> 2 | C42: =SUMIFS(Backlog!$J$2:$J$75,Backlog!$C$2:$C$75,A42) -> 6 | D42: =SUMIFS(Backlog!$J$2:$J$75,Backlog!$C$2:$C$75,A42,Backlog!$N$2:$N$75,"Done") -> 0 | E42: =IF($B$4>0,C42/$B$4,0) -> 0.3
A43: Data governance | B43: =COUNTIF(Backlog!$C$2:$C$75,A43) -> 1 | C43: =SUMIFS(Backlog!$J$2:$J$75,Backlog!$C$2:$C$75,A43) -> 3 | D43: =SUMIFS(Backlog!$J$2:$J$75,Backlog!$C$2:$C$75,A43,Backlog!$N$2:$N$75,"Done") -> 0 | E43: =IF($B$4>0,C43/$B$4,0) -> 0.15
A44: Data migration | B44: =COUNTIF(Backlog!$C$2:$C$75,A44) -> 1 | C44: =SUMIFS(Backlog!$J$2:$J$75,Backlog!$C$2:$C$75,A44) -> 3 | D44: =SUMIFS(Backlog!$J$2:$J$75,Backlog!$C$2:$C$75,A44,Backlog!$N$2:$N$75,"Done") -> 0 | E44: =IF($B$4>0,C44/$B$4,0) -> 0.15
... A62: Validation | B62: =COUNTIF(Backlog!$C$2:$C$75,A62) -> 1 | C62: =SUMIFS(Backlog!$J$2:$J$75,Backlog!$C$2:$C$75,A62) -> 3 | D62: =SUMIFS(Backlog!$J$2:$J$75,Backlog!$C$2:$C$75,A62,Backlog!$N$2:$N$75,"Done") -> 0 | E62: =IF($B$4>0,C62/$B$4,0) -> 0.15
A63: Total | B63: =SUM(B33:B62) -> 74 | C63: =SUM(C33:C62) -> 246 | D63: =SUM(D33:D62) -> 0 | E63: =SUM(E33:E62) -> 12.3
...

Sheet Legend
A1: Legend and how to use this workbook
A2: Edit only the blue cells and the backlog columns Size, Intensity, Priority, Status, Owner. Story points and the Summary sheet recalculate from them.
A4: T-shirt size | B4: Story points | C4: Meaning
A5: S | B5: 2 | C5: Small, well understood change in one layer; little regression impact | D5: Points per size as given by you (S=2, M=3, L=8); change the blue cells to re-weight.
A6: M | B6: 3 | C6: Moderate change, a few rules or instances; some design or testing effort
A7: L | B7: 8 | C7: Large or cross-cutting change; refactoring, several layers, or heavy regression
A9: Intensity | C9: Meaning (technical risk and regression impact)
A10: High | C10: Touches framework or security/isolation; failure affects Trinity or data separation
A11: Medium | C11: Some design choices or cross-layer effects; contained regression
A12: Low | C12: Configuration or AF-only change with local impact
A14: Priority | C14: Meaning
A15: P1 - Must | C15: Needed for Adrian Flux go-live
A16: P2 - Should | C16: Important; can follow shortly after go-live or ship if capacity allows
A17: P3 - Could | C17: Only if Adrian Flux needs it, or nice to have
A19: Status | C19: Meaning
A20: Not started
A21: In progress
A22: Blocked
A23: Done
A25: Story IDs: F = Phase 0 framework refactor (CS), A = Phase 1 AF foundation (CSAF), W = Phase 2 AF web form (CSAFWebExt), S = Phase 3 AF specializations, T = Phase 4 test and go-live. Section numbers refer to the framework document.

Sheet Backlog
A1: ID | B1: Phase | C1: Category | D1: Story title | E1: Description / scope | F1: Acceptance criteria | G1: Layer / app | H1: Doc section | I1: Size | J1: Story points | K1: Intensity | L1: Priority | M1: Depends on | N1: Status | O1: Owner / notes
A2: F-01 | B2: 0 - Framework refactor (CS) | C2: Analysis | D2: Capability inventory and rule tagging | E2: List every Trinity capability and its rules; tag each Framework / Extend / Specialize. | F2: Inventory signed off; every rule in the FNOL flow tagged; extension point list agreed. | G2: CS | H2: 2, 13 | I2: M | J2: =IFERROR(INDEX(Legend!$B$5:$B$7,MATCH(I2,Legend!$A$5:$A$7,0)),0) -> 3 | K2: Medium | L2: P1 - Must | N2: Not started
A3: F-02 | B3: 0 - Framework refactor (CS) | C3: Refactoring | D3: Scan CS rulesets for coverholder literals | E3: Search CS and CSWebExt for 'Trinity', TRI-, mailbox domains, class names, case type IDs, logos. | F3: Report of all hits with owning rule; each hit mapped to a refactoring story. | G3: CS | H3: 2, 16 | I3: S | J3: =IFERROR(INDEX(Legend!$B$5:$B$7,MATCH(I3,Legend!$A$5:$A$7,0)),0) -> 2 | K3: Low | L3: P1 - Must | M3: F-01 | N3: Not started
A4: F-03 | B4: 0 - Framework refactor (CS) | C4: Configuration | D4: Coverholder configuration data type | E4: Create HCC-CS-Data-CoverholderConfig, table and D_CoverholderConfig (node, keyed by CoverholderCode); add TRI row. | F4: Data page returns TRI row; refresh on table change; PegaUnit on lookup. | G4: CS | H4: 6 | I4: M | J4: =IFERROR(INDEX(Legend!$B$5:$B$7,MATCH(I4,Legend!$A$5:$A$7,0)),0) -> 3 | K4: Medium | L4: P1 - Must | M4: F-01 | N4: Not started
A5: F-04 | B5: 0 - Framework refactor (CS) | C5: Configuration / DCR | D5: Application context data page | E5: Create HCC-CS-Data-AppContext, D_CSAppContext (requestor) and LoadAppContext with Trinity values. | F5: D_CSAppContext returns TRI and class names in CS context; documented as overridable per ruleset. | G5: CS | H5: 6 | I5: M | J5: =IFERROR(INDEX(Legend!$B$5:$B$7,MATCH(I5,Legend!$A$5:$A$7,0)),0) -> 3 | K5: Medium | L5: P1 - Must | M5: F-03 | N5: Not started
A6: F-05 | B6: 0 - Framework refactor (CS) | C6: Data model | D6: CoverholderCode on cases | E6: Add .CoverholderCode to HCC-CS-Work; set in pyDefault of HCC-CS-Work-FNOL; expose as column. | F6: New Trinity cases carry TRI; column populated and indexed. | G6: CS | H6: 6 | I6: S | J6: =IFERROR(INDEX(Legend!$B$5:$B$7,MATCH(I6,Legend!$A$5:$A$7,0)),0) -> 2 | K6: Low | L6: P1 - Must | M6: F-03 | N6: Not started
A7: F-06 | B7: 0 - Framework refactor (CS) | C7: Data migration | D7: Backfill CoverholderCode on existing cases | E7: Backfill TRI on open and closed Trinity FNOL and triage cases. | F7: All existing cases have TRI; reconciliation count matches; run log kept. | G7: CS | H7: 6, 16 | I7: M | J7: =IFERROR(INDEX(Legend!$B$5:$B$7,MATCH(I7,Legend!$A$5:$A$7,0)),0) -> 3 | K7: Medium | L7: P1 - Must | M7: F-05 | N7: Not started
A8: F-07 | B8: 0 - Framework refactor (CS) | C8: Configuration / DCR | D8: GetCoverholderCode resolver | E8: Shared rule: case .CoverholderCode first, else D_CSAppContext. | F8: Unit tests for case, case-less and background contexts. | G8: CS | H8: 6 | I8: S | J8: =IFERROR(INDEX(Legend!$B$5:$B$7,MATCH(I8,Legend!$A$5:$A$7,0)),0) -> 2 | K8: Low | L8: P1 - Must | M8: F-04, F-05 | N8: Not started
A9: F-08 | B9: 0 - Framework refactor (CS) | C9: Refactoring | D9: Replace hard-coded values with config lookups | E9: Replace literal class names, email accounts, prefixes, patterns, mailboxes found in F-02. | F9: Zero literal hits in re-scan (except Trinity _Ext defaults); Trinity regression green. | G9: CS | H9: 3, 6 | I9: L | J9: =IFERROR(INDEX(Legend!$B$5:$B$7,MATCH(I9,Legend!$A$5:$A$7,0)),0) -> 8 | K9: High | L9: P1 - Must | M9: F-02, F-07 | N9: Not started
A10: F-09 | B10: 0 - Framework refactor (CS) | C10: Case processing | D10: Refactor NewDefaults into template + extensions | E10: Split NewDefaults; create DuplicateCheckCriteria_Ext, IsDuplicate_Ext, OnDuplicateFound_Ext, NewDefaults_Ext with Trinity defaults. | F10: Trinity duplicate outcomes identical on regression set; PegaUnit per _Ext. | G10: CS | H10: 10 | I10: L | J10: =IFERROR(INDEX(Legend!$B$5:$B$7,MATCH(I10,Legend!$A$5:$A$7,0)),0) -> 8 | K10: High | L10: P1 - Must | M10: F-01 | N10: Not started
A11: F-10 | B11: 0 - Framework refactor (CS) | C11: Case processing | D11: Class-aware duplicate candidate data page | E11: D_DuplicateCandidates runs the duplicate report in the case's own class. | F11: Query hits only the case's table; response time within agreed limit. | G11: CS | H11: 10 | I11: M | J11: =IFERROR(INDEX(Legend!$B$5:$B$7,MATCH(I11,Legend!$A$5:$A$7,0)),0) -> 3 | K11: Medium | L11: P1 - Must | M11: F-09 | N11: Not started
A12: F-11 | B12: 0 - Framework refactor (CS) | C12: Correspondence | D12: Refactor confirmation correspondence | E12: Split shared and coverholder paragraphs; sender account from config; ConfirmationRecipients_Ext. | F12: Trinity emails unchanged; account name not hard-coded. | G12: CS | H12: 11 | I12: M | J12: =IFERROR(INDEX(Legend!$B$5:$B$7,MATCH(I12,Legend!$A$5:$A$7,0)),0) -> 3 | K12: Medium | L12: P1 - Must | M12: F-03 | N12: Not started
A13: F-12 | B13: 0 - Framework refactor (CS) | C13: Document generation | D13: Refactor claim summary PDF | E13: Shared claim-details section; ClaimSummaryPDF override point; file name prefix and category from config. | F13: Trinity PDF identical; file name built from config. | G13: CS | H13: 11 | I13: M | J13: =IFERROR(INDEX(Legend!$B$5:$B$7,MATCH(I13,Legend!$A$5:$A$7,0)),0) -> 3 | K13: Medium | L13: P1 - Must | M13: F-03 | N13: Not started
A14: F-13 | B14: 0 - Framework refactor (CS) | C14: AI | D14: Refactor AI image analysis configuration | E14: Move prompt and thresholds to config or ImageAnalysisPrompt_Ext; confirm QP context handling. | F14: Trinity analysis results unchanged; no literal prompt in framework activity. | G14: CS | H14: 11, 14 | I14: M | J14: =IFERROR(INDEX(Legend!$B$5:$B$7,MATCH(I14,Legend!$A$5:$A$7,0)),0) -> 3 | K14: Medium | L14: P1 - Must | M14: F-03, F-26 | N14: Not started
... A23: F-22 | B23: 0 - Framework refactor (CS) | C23: UI / DX component | D23: Move component to shared component ruleset | E23: Publish the custom component into a shared CS component ruleset. | F23: Single component version used by CSWebExt; old copy withdrawn. | G23: CS | H23: 4, 8 | I23: S | J23: =IFERROR(INDEX(Legend!$B$5:$B$7,MATCH(I23,Legend!$A$5:$A$7,0)),0) -> 2 | K23: Medium | L23: P1 - Must | M23: F-21 | N23: Not started
A24: F-23 | B24: 0 - Framework refactor (CS) | C24: DevOps | D24: Bundle key-parity check | E24: Pipeline script comparing keys across web app bundles. | F24: Pipeline fails on missing keys. | G24: DevOps | H24: 8 | I24: S | J24: =IFERROR(INDEX(Legend!$B$5:$B$7,MATCH(I24,Legend!$A$5:$A$7,0)),0) -> 2 | K24: Low | L24: P2 - Should | N24: Not started
A25: F-24 | B25: 0 - Framework refactor (CS) | C25: Governance | D25: Extension point catalogue | E25: Document each _Ext rule: purpose, inputs, outputs, default. | F25: Catalogue published and linked from rule descriptions. | G25: CS | H25: 13 | I25: S | J25: =IFERROR(INDEX(Legend!$B$5:$B$7,MATCH(I25,Legend!$A$5:$A$7,0)),0) -> 2 | K25: Low | L25: P2 - Should | M25: F-09, F-15 | N25: Not started
A26: F-25 | B26: 0 - Framework refactor (CS) | C26: Testing | D26: Trinity regression and CS framework release | E26: Full Trinity regression after Phase 0; release CS version. | F26: Regression results identical to baseline; CS version locked. | G26: CS | H26: 15, 16 | I26: L | J26: =IFERROR(INDEX(Legend!$B$5:$B$7,MATCH(I26,Legend!$A$5:$A$7,0)),0) -> 8 | K26: High | L26: P1 - Must | M26: F-08 to F-22 | N26: Not started
A27: F-26 | B27: 0 - Framework refactor (CS) | C27: Architecture | D27: Background processing inventory | E27: List QPs, job schedulers, agents, SLAs in FNOL flow and their access-group context. | F27: Inventory with decision per item: separate AF instance or case-resolved. | G27: CS | H27: 14 | I27: M | J27: =IFERROR(INDEX(Legend!$B$5:$B$7,MATCH(I27,Legend!$A$5:$A$7,0)),0) -> 3 | K27: Medium | L27: P1 - Must | M27: F-01 | N27: Not started
A28: F-27 | B28: 0 - Framework refactor (CS) | C28: Governance | D28: Framework governance model | E28: Versioning of CS, change requests with impact assessment for all coverholders, design authority, extension contract and deprecation policy. | F28: Process approved and published. | G28: All | H28: 15 | I28: S | J28: =IFERROR(INDEX(Legend!$B$5:$B$7,MATCH(I28,Legend!$A$5:$A$7,0)),0) -> 2 | K28: Low | L28: P2 - Should | N28: Not started
A29: A-01 | B29: 1 - AF foundation (CSAF) | C29: Architecture | D29: Create CSAF application | E29: CSAF built on CS; rulesets CSAF, CSAFInt, CSAFData; case types list. | F29: Application opens; only AF case types shown. | G29: CSAF | H29: 4 | I29: S | J29: =IFERROR(INDEX(Legend!$B$5:$B$7,MATCH(I29,Legend!$A$5:$A$7,0)),0) -> 2 | K29: Low | L29: P1 - Must | M29: F-25 | N29: Not started
A30: A-02 | B30: 1 - AF foundation (CSAF) | C30: Data model | D30: AF class group and classes | E30: HCC-CSAF-Work class group, HCC-CSAF-Work-FNOL with directed parent HCC-CS-Work-FNOL; table mappings. | F30: Classes created; rule resolution shows CS rules inherited. | G30: CSAF | H30: 5 | I30: M | J30: =IFERROR(INDEX(Legend!$B$5:$B$7,MATCH(I30,Legend!$A$5:$A$7,0)),0) -> 3 | K30: Medium | L30: P1 - Must | M30: A-01 | N30: Not started
A31: A-03 | B31: 1 - AF foundation (CSAF) | C31: Database | D31: AF database tables (DDL) | E31: Case, history and index tables with columns matching CS exposed columns plus duplicate-check indexes. | F31: DDL executed in all environments; column parity verified. | G31: DBA | H31: 5 | I31: M | J31: =IFERROR(INDEX(Legend!$B$5:$B$7,MATCH(I31,Legend!$A$5:$A$7,0)),0) -> 3 | K31: Medium | L31: P1 - Must | M31: A-02 | N31: Not started
A32: A-04 | B32: 1 - AF foundation (CSAF) | C32: Case processing | D32: AF case type | E32: Thin case type rule calling CS processes; work ID prefix; pyDefault sets AF. | F32: AF case created with correct prefix and CoverholderCode AF. | G32: CSAF | H32: 10 | I32: M | J32: =IFERROR(INDEX(Legend!$B$5:$B$7,MATCH(I32,Legend!$A$5:$A$7,0)),0) -> 3 | K32: Medium | L32: P1 - Must | M32: A-02, A-03 | N32: Not started
A33: A-05 | B33: 1 - AF foundation (CSAF) | C33: Testing | D33: Stage-list comparison test | E33: Unit test comparing CS and AF case type stages. | F33: Test fails when stages diverge unexpectedly. | G33: CSAF | H33: 10 | I33: S | J33: =IFERROR(INDEX(Legend!$B$5:$B$7,MATCH(I33,Legend!$A$5:$A$7,0)),0) -> 2 | K33: Low | L33: P2 - Should | M33: A-04 | N33: Not started
A34: A-06 | B34: 1 - AF foundation (CSAF) | C34: Configuration | D34: AF config row and context override | E34: AF row in config table; LoadAppContext override in CSAF ruleset. | F34: D_CSAppContext returns AF in CSAF context. | G34: CSAF | H34: 6 | I34: S | J34: =IFERROR(INDEX(Legend!$B$5:$B$7,MATCH(I34,Legend!$A$5:$A$7,0)),0) -> 2 | K34: Low | L34: P1 - Must | M34: A-01, F-04 | N34: Not started
A35: A-07 | B35: 1 - AF foundation (CSAF) | C35: Data model | D35: AF LOV data type | E35: HCC-CSAF-Data-LOV, own table, AF-only properties, data load, added to app data types. | F35: AF dropdowns load AF values via shared data pages. | G35: CSAF | H35: 9 | I35: M | J35: =IFERROR(INDEX(Legend!$B$5:$B$7,MATCH(I35,Legend!$A$5:$A$7,0)),0) -> 3 | K35: Medium | L35: P1 - Must | M35: A-02, F-20 | N35: Not started
A36: A-08 | B36: 1 - AF foundation (CSAF) | C36: Data model | D36: Other AF data tables | E36: Apply LOV pattern to other web form / validation tables. | F36: Each table loads AF data through shared data pages. | G36: CSAF | H36: 9 | I36: M | J36: =IFERROR(INDEX(Legend!$B$5:$B$7,MATCH(I36,Legend!$A$5:$A$7,0)),0) -> 3 | K36: Medium | L36: P2 - Should | M36: A-07 | N36: Not started
A37: A-09 | B37: 1 - AF foundation (CSAF) | C37: Security | D37: AF roles, AROs and access groups | E37: Access roles depending on CS roles; AROs on HCC-CSAF-; access groups ClaimHandler, Supervisor, Background, Admin. | F37: AF users access only AF cases; Trinity users cannot open AF cases. | G37: CSAF | H37: 7 | I37: M | J37: =IFERROR(INDEX(Legend!$B$5:$B$7,MATCH(I37,Legend!$A$5:$A$7,0)),0) -> 3 | K37: High | L37: P1 - Must | M37: A-02 | N37: Not started
A38: A-10 | B38: 1 - AF foundation (CSAF) | C38: Security | D38: Triage case isolation by coverholder | E38: Access When / access control policy on .CoverholderCode for Work-Channel-Triage-Email. | F38: Each coverholder sees only its own triage cases in UI, search and reports. | G38: CS / CSAF | H38: 7 | I38: M | J38: =IFERROR(INDEX(Legend!$B$5:$B$7,MATCH(I38,Legend!$A$5:$A$7,0)),0) -> 3 | K38: High | L38: P1 - Must | M38: F-16, A-09 | N38: Not started
A39: A-11 | B39: 1 - AF foundation (CSAF) | C39: Routing | D39: AF work groups and work queues | E39: CSAF_FNOL_Review, CSAF_Exceptions etc.; routing override. | F39: AF assignments land only in AF queues. | G39: CSAF | H39: 14 | I39: S | J39: =IFERROR(INDEX(Legend!$B$5:$B$7,MATCH(I39,Legend!$A$5:$A$7,0)),0) -> 2 | K39: Low | L39: P1 - Must | M39: A-09, F-18 | N39: Not started
A40: A-12 | B40: 1 - AF foundation (CSAF) | C40: Security / SSO | D40: Okta group mapping for AF users | E40: Okta group(s) mapped to CSAF access groups in the authentication service. | F40: AF user logs in via Okta into CSAF portal with correct access group. | G40: CS / CSAF | H40: 7 | I40: M | J40: =IFERROR(INDEX(Legend!$B$5:$B$7,MATCH(I40,Legend!$A$5:$A$7,0)),0) -> 3 | K40: Medium | L40: P1 - Must | M40: A-09 | N40: Not started
... A56: S-05 | B56: 3 - AF specializations | C56: Integration / email | D56: AF validation email | E56: AF template, recipient mailbox, subject with AF ID pattern. | F56: AF validation team receives request with parsable subject. | G56: CSAF | H56: 12 | I56: S | J56: =IFERROR(INDEX(Legend!$B$5:$B$7,MATCH(I56,Legend!$A$5:$A$7,0)),0) -> 2 | K56: Low | L56: P1 - Must | M56: F-14 | N56: Not started
A57: S-06 | B57: 3 - AF specializations | C57: Integration / email | D57: AF email accounts | E57: Inbound and outbound AF email accounts with modern auth; secrets in auth profile. | F57: Accounts connect in all environments. | G57: CSAF | H57: 12 | I57: S | J57: =IFERROR(INDEX(Legend!$B$5:$B$7,MATCH(I57,Legend!$A$5:$A$7,0)),0) -> 2 | K57: Medium | L57: P1 - Must | N57: Not started
A58: S-07 | B58: 3 - AF specializations | C58: Integration / email | D58: AF email channel and listener | E58: Email channel in CSAF; generated listener and service email; service package access group CSAF:Background. | F58: AF reply creates triage case in CSAF context with CoverholderCode AF. | G58: CSAF | H58: 12 | I58: M | J58: =IFERROR(INDEX(Legend!$B$5:$B$7,MATCH(I58,Legend!$A$5:$A$7,0)),0) -> 3 | K58: High | L58: P1 - Must | M58: S-06, A-09, F-16 | N58: Not started
A59: S-08 | B59: 3 - AF specializations | C59: AI / email | D59: AF triage extension overrides | E59: Override triage _Ext rules in CSAF ruleset only where AF replies differ. | F59: AF replies classified, linked and parsed; Trinity unaffected. | G59: CSAF | H59: 6, 12 | I59: M | J59: =IFERROR(INDEX(Legend!$B$5:$B$7,MATCH(I59,Legend!$A$5:$A$7,0)),0) -> 3 | K59: High | L59: P1 - Must | M59: F-15, S-07 | N59: Not started
A60: S-09 | B60: 3 - AF specializations | C60: AI | D60: AF NLP / text analytics model | E60: Separate AF model only if AF reply format differs materially. | F60: Model accuracy on AF sample meets agreed threshold. | G60: CSAF | H60: 12 | I60: L | J60: =IFERROR(INDEX(Legend!$B$5:$B$7,MATCH(I60,Legend!$A$5:$A$7,0)),0) -> 8 | K60: High | L60: P2 - Should | M60: S-08 | N60: Not started
A61: S-10 | B61: 3 - AF specializations | C61: AI / business rules | D61: AF parsed-data mapping and validations | E61: AF overrides of MapParsedPolicyData_Ext and ApplyPolicyValidations_Ext. | F61: AF review tabs show correct data and AF validation outcomes. | G61: CSAF | H61: 12 | I61: L | J61: =IFERROR(INDEX(Legend!$B$5:$B$7,MATCH(I61,Legend!$A$5:$A$7,0)),0) -> 8 | K61: High | L61: P1 - Must | M61: F-17, S-08 | N61: Not started
A62: S-11 | B62: 3 - AF specializations | C62: UI | D62: AF review view overrides | E62: View overrides only for AF-only fields. | F62: AF-only fields visible on review tabs. | G62: CSAF | H62: 12 | I62: S | J62: =IFERROR(INDEX(Legend!$B$5:$B$7,MATCH(I62,Legend!$A$5:$A$7,0)),0) -> 2 | K62: Low | L62: P2 - Should | M62: S-10 | N62: Not started
A63: S-12 | B63: 3 - AF specializations | C63: Background processing | D63: AF queue processors and job schedulers | E63: AF instances with CSAF:Background, or verified case-resolved, per F-26. | F63: AF background items use AF templates, accounts and rules. | G63: CSAF | H63: 14 | I63: M | J63: =IFERROR(INDEX(Legend!$B$5:$B$7,MATCH(I63,Legend!$A$5:$A$7,0)),0) -> 3 | K63: High | L63: P1 - Must | M63: F-26, A-09 | N63: Not started
...
